[2022-07-13 10:22:53,139] {taskinstance.py:1179} INFO - Dependencies all met for <TaskInstance: python_operator_dag_v6.Greeting manual__2022-07-13T10:22:51.319789+00:00 [queued]>
[2022-07-13 10:22:53,158] {taskinstance.py:1179} INFO - Dependencies all met for <TaskInstance: python_operator_dag_v6.Greeting manual__2022-07-13T10:22:51.319789+00:00 [queued]>
[2022-07-13 10:22:53,160] {taskinstance.py:1376} INFO - 
--------------------------------------------------------------------------------
[2022-07-13 10:22:53,161] {taskinstance.py:1377} INFO - Starting attempt 1 of 6
[2022-07-13 10:22:53,162] {taskinstance.py:1378} INFO - 
--------------------------------------------------------------------------------
[2022-07-13 10:22:53,187] {taskinstance.py:1397} INFO - Executing <Task(PythonOperator): Greeting> on 2022-07-13 10:22:51.319789+00:00
[2022-07-13 10:22:53,192] {standard_task_runner.py:52} INFO - Started process 7016 to run task
[2022-07-13 10:22:53,198] {standard_task_runner.py:79} INFO - Running: ['***', 'tasks', 'run', 'python_operator_dag_v6', 'Greeting', 'manual__2022-07-13T10:22:51.319789+00:00', '--job-id', '49', '--raw', '--subdir', 'DAGS_FOLDER/python_operator_dag.py', '--cfg-path', '/tmp/tmpmwv8llil', '--error-file', '/tmp/tmpgoq3kq3r']
[2022-07-13 10:22:53,201] {standard_task_runner.py:80} INFO - Job 49: Subtask Greeting
[2022-07-13 10:22:53,311] {task_command.py:371} INFO - Running <TaskInstance: python_operator_dag_v6.Greeting manual__2022-07-13T10:22:51.319789+00:00 [running]> on host 8e2218deeaf2
[2022-07-13 10:22:53,439] {taskinstance.py:1591} INFO - Exporting the following env vars:
AIRFLOW_CTX_DAG_OWNER=harshab
AIRFLOW_CTX_DAG_ID=python_operator_dag_v6
AIRFLOW_CTX_TASK_ID=Greeting
AIRFLOW_CTX_EXECUTION_DATE=2022-07-13T10:22:51.319789+00:00
AIRFLOW_CTX_TRY_NUMBER=1
AIRFLOW_CTX_DAG_RUN_ID=manual__2022-07-13T10:22:51.319789+00:00
[2022-07-13 10:22:53,470] {taskinstance.py:1909} ERROR - Task failed with exception
Traceback (most recent call last):
  File "/home/airflow/.local/lib/python3.7/site-packages/airflow/operators/python.py", line 171, in execute
    return_value = self.execute_callable()
  File "/home/airflow/.local/lib/python3.7/site-packages/airflow/operators/python.py", line 189, in execute_callable
    return self.python_callable(*self.op_args, **self.op_kwargs)
  File "/opt/airflow/dags/python_operator_dag.py", line 16, in greet
    print(f"hello World! My name is {name},"
NameError: name 'name' is not defined
[2022-07-13 10:22:53,485] {taskinstance.py:1420} INFO - Marking task as UP_FOR_RETRY. dag_id=python_operator_dag_v6, task_id=Greeting, execution_date=20220713T102251, start_date=20220713T102253, end_date=20220713T102253
[2022-07-13 10:22:53,505] {standard_task_runner.py:97} ERROR - Failed to execute job 49 for task Greeting (name 'name' is not defined; 7016)
[2022-07-13 10:22:53,533] {local_task_job.py:156} INFO - Task exited with return code 1
[2022-07-13 10:22:53,588] {local_task_job.py:273} INFO - 0 downstream tasks scheduled from follow-on schedule check
