[2022-07-13 09:56:39,446] {taskinstance.py:1179} INFO - Dependencies all met for <TaskInstance: python_operator_dag_v5.Greeting manual__2022-07-13T09:50:33.919862+00:00 [queued]>
[2022-07-13 09:56:39,463] {taskinstance.py:1179} INFO - Dependencies all met for <TaskInstance: python_operator_dag_v5.Greeting manual__2022-07-13T09:50:33.919862+00:00 [queued]>
[2022-07-13 09:56:39,464] {taskinstance.py:1376} INFO - 
--------------------------------------------------------------------------------
[2022-07-13 09:56:39,465] {taskinstance.py:1377} INFO - Starting attempt 4 of 6
[2022-07-13 09:56:39,466] {taskinstance.py:1378} INFO - 
--------------------------------------------------------------------------------
[2022-07-13 09:56:39,486] {taskinstance.py:1397} INFO - Executing <Task(PythonOperator): Greeting> on 2022-07-13 09:50:33.919862+00:00
[2022-07-13 09:56:39,491] {standard_task_runner.py:52} INFO - Started process 5228 to run task
[2022-07-13 09:56:39,496] {standard_task_runner.py:79} INFO - Running: ['***', 'tasks', 'run', 'python_operator_dag_v5', 'Greeting', 'manual__2022-07-13T09:50:33.919862+00:00', '--job-id', '39', '--raw', '--subdir', 'DAGS_FOLDER/python_operator_dag.py', '--cfg-path', '/tmp/tmpdnvngiao', '--error-file', '/tmp/tmpgq7pi9le']
[2022-07-13 09:56:39,499] {standard_task_runner.py:80} INFO - Job 39: Subtask Greeting
[2022-07-13 09:56:39,589] {task_command.py:371} INFO - Running <TaskInstance: python_operator_dag_v5.Greeting manual__2022-07-13T09:50:33.919862+00:00 [running]> on host 8e2218deeaf2
[2022-07-13 09:56:39,689] {taskinstance.py:1591} INFO - Exporting the following env vars:
AIRFLOW_CTX_DAG_OWNER=harshab
AIRFLOW_CTX_DAG_ID=python_operator_dag_v5
AIRFLOW_CTX_TASK_ID=Greeting
AIRFLOW_CTX_EXECUTION_DATE=2022-07-13T09:50:33.919862+00:00
AIRFLOW_CTX_TRY_NUMBER=4
AIRFLOW_CTX_DAG_RUN_ID=manual__2022-07-13T09:50:33.919862+00:00
[2022-07-13 09:56:39,692] {taskinstance.py:1909} ERROR - Task failed with exception
Traceback (most recent call last):
  File "/home/airflow/.local/lib/python3.7/site-packages/airflow/operators/python.py", line 171, in execute
    return_value = self.execute_callable()
  File "/home/airflow/.local/lib/python3.7/site-packages/airflow/operators/python.py", line 189, in execute_callable
    return self.python_callable(*self.op_args, **self.op_kwargs)
  File "/opt/airflow/dags/python_operator_dag.py", line 14, in greet
    name = ti.xcoms_pull(task_ids='get_name')
AttributeError: 'TaskInstance' object has no attribute 'xcoms_pull'
[2022-07-13 09:56:39,706] {taskinstance.py:1420} INFO - Marking task as UP_FOR_RETRY. dag_id=python_operator_dag_v5, task_id=Greeting, execution_date=20220713T095033, start_date=20220713T095639, end_date=20220713T095639
[2022-07-13 09:56:39,720] {standard_task_runner.py:97} ERROR - Failed to execute job 39 for task Greeting ('TaskInstance' object has no attribute 'xcoms_pull'; 5228)
[2022-07-13 09:56:39,750] {local_task_job.py:156} INFO - Task exited with return code 1
[2022-07-13 09:56:39,798] {local_task_job.py:273} INFO - 0 downstream tasks scheduled from follow-on schedule check
