[2022-07-13 09:55:58,375] {taskinstance.py:1179} INFO - Dependencies all met for <TaskInstance: python_operator_dag_v5.Greeting manual__2022-07-13T09:47:52.481528+00:00 [queued]>
[2022-07-13 09:55:58,392] {taskinstance.py:1179} INFO - Dependencies all met for <TaskInstance: python_operator_dag_v5.Greeting manual__2022-07-13T09:47:52.481528+00:00 [queued]>
[2022-07-13 09:55:58,393] {taskinstance.py:1376} INFO - 
--------------------------------------------------------------------------------
[2022-07-13 09:55:58,394] {taskinstance.py:1377} INFO - Starting attempt 5 of 6
[2022-07-13 09:55:58,395] {taskinstance.py:1378} INFO - 
--------------------------------------------------------------------------------
[2022-07-13 09:55:58,415] {taskinstance.py:1397} INFO - Executing <Task(PythonOperator): Greeting> on 2022-07-13 09:47:52.481528+00:00
[2022-07-13 09:55:58,420] {standard_task_runner.py:52} INFO - Started process 5182 to run task
[2022-07-13 09:55:58,425] {standard_task_runner.py:79} INFO - Running: ['***', 'tasks', 'run', 'python_operator_dag_v5', 'Greeting', 'manual__2022-07-13T09:47:52.481528+00:00', '--job-id', '37', '--raw', '--subdir', 'DAGS_FOLDER/python_operator_dag.py', '--cfg-path', '/tmp/tmpesyzmzal', '--error-file', '/tmp/tmpn_rqlv4f']
[2022-07-13 09:55:58,427] {standard_task_runner.py:80} INFO - Job 37: Subtask Greeting
[2022-07-13 09:55:58,520] {task_command.py:371} INFO - Running <TaskInstance: python_operator_dag_v5.Greeting manual__2022-07-13T09:47:52.481528+00:00 [running]> on host 8e2218deeaf2
[2022-07-13 09:55:58,617] {taskinstance.py:1591} INFO - Exporting the following env vars:
AIRFLOW_CTX_DAG_OWNER=harshab
AIRFLOW_CTX_DAG_ID=python_operator_dag_v5
AIRFLOW_CTX_TASK_ID=Greeting
AIRFLOW_CTX_EXECUTION_DATE=2022-07-13T09:47:52.481528+00:00
AIRFLOW_CTX_TRY_NUMBER=5
AIRFLOW_CTX_DAG_RUN_ID=manual__2022-07-13T09:47:52.481528+00:00
[2022-07-13 09:55:58,619] {taskinstance.py:1909} ERROR - Task failed with exception
Traceback (most recent call last):
  File "/home/airflow/.local/lib/python3.7/site-packages/airflow/operators/python.py", line 171, in execute
    return_value = self.execute_callable()
  File "/home/airflow/.local/lib/python3.7/site-packages/airflow/operators/python.py", line 189, in execute_callable
    return self.python_callable(*self.op_args, **self.op_kwargs)
  File "/opt/airflow/dags/python_operator_dag.py", line 14, in greet
    name = ti.xcoms_pull(task_ids='get_name')
AttributeError: 'TaskInstance' object has no attribute 'xcoms_pull'
[2022-07-13 09:55:58,633] {taskinstance.py:1420} INFO - Marking task as UP_FOR_RETRY. dag_id=python_operator_dag_v5, task_id=Greeting, execution_date=20220713T094752, start_date=20220713T095558, end_date=20220713T095558
[2022-07-13 09:55:58,648] {standard_task_runner.py:97} ERROR - Failed to execute job 37 for task Greeting ('TaskInstance' object has no attribute 'xcoms_pull'; 5182)
[2022-07-13 09:55:58,680] {local_task_job.py:156} INFO - Task exited with return code 1
[2022-07-13 09:55:58,729] {local_task_job.py:273} INFO - 0 downstream tasks scheduled from follow-on schedule check
