[2022-07-13 09:55:15,652] {taskinstance.py:1179} INFO - Dependencies all met for <TaskInstance: python_operator_dag_v5.Greeting manual__2022-07-13T09:49:09.531547+00:00 [queued]>
[2022-07-13 09:55:15,670] {taskinstance.py:1179} INFO - Dependencies all met for <TaskInstance: python_operator_dag_v5.Greeting manual__2022-07-13T09:49:09.531547+00:00 [queued]>
[2022-07-13 09:55:15,671] {taskinstance.py:1376} INFO - 
--------------------------------------------------------------------------------
[2022-07-13 09:55:15,672] {taskinstance.py:1377} INFO - Starting attempt 4 of 6
[2022-07-13 09:55:15,672] {taskinstance.py:1378} INFO - 
--------------------------------------------------------------------------------
[2022-07-13 09:55:15,693] {taskinstance.py:1397} INFO - Executing <Task(PythonOperator): Greeting> on 2022-07-13 09:49:09.531547+00:00
[2022-07-13 09:55:15,698] {standard_task_runner.py:52} INFO - Started process 5129 to run task
[2022-07-13 09:55:15,703] {standard_task_runner.py:79} INFO - Running: ['***', 'tasks', 'run', 'python_operator_dag_v5', 'Greeting', 'manual__2022-07-13T09:49:09.531547+00:00', '--job-id', '36', '--raw', '--subdir', 'DAGS_FOLDER/python_operator_dag.py', '--cfg-path', '/tmp/tmpnigsvy7a', '--error-file', '/tmp/tmpbop1g855']
[2022-07-13 09:55:15,706] {standard_task_runner.py:80} INFO - Job 36: Subtask Greeting
[2022-07-13 09:55:15,799] {task_command.py:371} INFO - Running <TaskInstance: python_operator_dag_v5.Greeting manual__2022-07-13T09:49:09.531547+00:00 [running]> on host 8e2218deeaf2
[2022-07-13 09:55:15,899] {taskinstance.py:1591} INFO - Exporting the following env vars:
AIRFLOW_CTX_DAG_OWNER=harshab
AIRFLOW_CTX_DAG_ID=python_operator_dag_v5
AIRFLOW_CTX_TASK_ID=Greeting
AIRFLOW_CTX_EXECUTION_DATE=2022-07-13T09:49:09.531547+00:00
AIRFLOW_CTX_TRY_NUMBER=4
AIRFLOW_CTX_DAG_RUN_ID=manual__2022-07-13T09:49:09.531547+00:00
[2022-07-13 09:55:15,902] {taskinstance.py:1909} ERROR - Task failed with exception
Traceback (most recent call last):
  File "/home/airflow/.local/lib/python3.7/site-packages/airflow/operators/python.py", line 171, in execute
    return_value = self.execute_callable()
  File "/home/airflow/.local/lib/python3.7/site-packages/airflow/operators/python.py", line 189, in execute_callable
    return self.python_callable(*self.op_args, **self.op_kwargs)
  File "/opt/airflow/dags/python_operator_dag.py", line 14, in greet
    name = ti.xcoms_pull(task_ids='get_name')
AttributeError: 'TaskInstance' object has no attribute 'xcoms_pull'
[2022-07-13 09:55:15,919] {taskinstance.py:1420} INFO - Marking task as UP_FOR_RETRY. dag_id=python_operator_dag_v5, task_id=Greeting, execution_date=20220713T094909, start_date=20220713T095515, end_date=20220713T095515
[2022-07-13 09:55:15,936] {standard_task_runner.py:97} ERROR - Failed to execute job 36 for task Greeting ('TaskInstance' object has no attribute 'xcoms_pull'; 5129)
[2022-07-13 09:55:15,957] {local_task_job.py:156} INFO - Task exited with return code 1
[2022-07-13 09:55:16,000] {local_task_job.py:273} INFO - 0 downstream tasks scheduled from follow-on schedule check
